Workbook
Name Autosys_output_commas: 'TRIS Autosys Jobs'!$A$3:$AM$145

Sheet Job Summary
A1: Legacy Job Name | B1: New TRIS JOB | C1: Tested
A2: TRIS_RH_ARCOS_Daily_Box | B2: =IF(_xlfn.XLOOKUP(A2,'Job Details'!A:A,'Job Details'!I:I,"Not in schedule")=0,"Pending",_xlfn.XLOOKUP(A2,'Job Details'!A:A,'Job Details'!I:I,"Not in schedule")) -> Pending | C2: =IF(_xlfn.XLOOKUP(A2,'Job Details'!A:A,'Job Details'!AU:AU,"Job Details")=0,"Pending",_xlfn.XLOOKUP(A2,'Job Details'!A:A,'Job Details'!AU:AU,"Not In Job Details")) -> Pending
A3: TRIS_RH_ARCOS_Overtime_Daily | B3: =IF(_xlfn.XLOOKUP(A3,'Job Details'!A:A,'Job Details'!I:I,"Not in schedule")=0,"Pending",_xlfn.XLOOKUP(A3,'Job Details'!A:A,'Job Details'!I:I,"Not in schedule")) -> Pending | C3: =IF(_xlfn.XLOOKUP(A3,'Job Details'!A:A,'Job Details'!AU:AU,"Job Details")=0,"Pending",_xlfn.XLOOKUP(A3,'Job Details'!A:A,'Job Details'!AU:AU,"Not In Job Details")) -> Pending
A4: TRIS_RH_ARCOS_HR_Daily | B4: =IF(_xlfn.XLOOKUP(A4,'Job Details'!A:A,'Job Details'!I:I,"Not in schedule")=0,"Pending",_xlfn.XLOOKUP(A4,'Job Details'!A:A,'Job Details'!I:I,"Not in schedule")) -> Pending | C4: =IF(_xlfn.XLOOKUP(A4,'Job Details'!A:A,'Job Details'!AU:AU,"Job Details")=0,"Pending",_xlfn.XLOOKUP(A4,'Job Details'!A:A,'Job Details'!AU:AU,"Not In Job Details")) -> Pending
A5: TRIS_RH_ARCOS_Sched_Daily | B5: =IF(_xlfn.XLOOKUP(A5,'Job Details'!A:A,'Job Details'!I:I,"Not in schedule")=0,"Pending",_xlfn.XLOOKUP(A5,'Job Details'!A:A,'Job Details'!I:I,"Not in schedule")) -> Pending | C5: =IF(_xlfn.XLOOKUP(A5,'Job Details'!A:A,'Job Details'!AU:AU,"Job Details")=0,"Pending",_xlfn.XLOOKUP(A5,'Job Details'!A:A,'Job Details'!AU:AU,"Not In Job Details")) -> Pending
A6: TRIS_RH_ARCOS_SFTP_Daily | B6: =IF(_xlfn.XLOOKUP(A6,'Job Details'!A:A,'Job Details'!I:I,"Not in schedule")=0,"Pending",_xlfn.XLOOKUP(A6,'Job Details'!A:A,'Job Details'!I:I,"Not in schedule")) -> Pending | C6: =IF(_xlfn.XLOOKUP(A6,'Job Details'!A:A,'Job Details'!AU:AU,"Job Details")=0,"Pending",_xlfn.XLOOKUP(A6,'Job Details'!A:A,'Job Details'!AU:AU,"Not In Job Details")) -> Pending
A7: TRIS_RH_ARCOS_Delete_files | B7: =IF(_xlfn.XLOOKUP(A7,'Job Details'!A:A,'Job Details'!I:I,"Not in schedule")=0,"Pending",_xlfn.XLOOKUP(A7,'Job Details'!A:A,'Job Details'!I:I,"Not in schedule")) -> Pending | C7: =IF(_xlfn.XLOOKUP(A7,'Job Details'!A:A,'Job Details'!AU:AU,"Job Details")=0,"Pending",_xlfn.XLOOKUP(A7,'Job Details'!A:A,'Job Details'!AU:AU,"Not In Job Details")) -> Pending
A8: TRIS_RH_ARCOS_Weekly_Box | B8: =IF(_xlfn.XLOOKUP(A8,'Job Details'!A:A,'Job Details'!I:I,"Not in schedule")=0,"Pending",_xlfn.XLOOKUP(A8,'Job Details'!A:A,'Job Details'!I:I,"Not in schedule")) -> Pending | C8: =IF(_xlfn.XLOOKUP(A8,'Job Details'!A:A,'Job Details'!AU:AU,"Job Details")=0,"Pending",_xlfn.XLOOKUP(A8,'Job Details'!A:A,'Job Details'!AU:AU,"Not In Job Details")) -> Pending
A9: TRIS_RH_ARCOS_Overtime_Weekly | B9: =IF(_xlfn.XLOOKUP(A9,'Job Details'!A:A,'Job Details'!I:I,"Not in schedule")=0,"Pending",_xlfn.XLOOKUP(A9,'Job Details'!A:A,'Job Details'!I:I,"Not in schedule")) -> Pending | C9: =IF(_xlfn.XLOOKUP(A9,'Job Details'!A:A,'Job Details'!AU:AU,"Job Details")=0,"Pending",_xlfn.XLOOKUP(A9,'Job Details'!A:A,'Job Details'!AU:AU,"Not In Job Details")) -> Pending
A10: TRIS_RH_ARCOS_Yearly_Box | B10: =IF(_xlfn.XLOOKUP(A10,'Job Details'!A:A,'Job Details'!I:I,"Not in schedule")=0,"Pending",_xlfn.XLOOKUP(A10,'Job Details'!A:A,'Job Details'!I:I,"Not in schedule")) -> Pending | C10: =IF(_xlfn.XLOOKUP(A10,'Job Details'!A:A,'Job Details'!AU:AU,"Job Details")=0,"Pending",_xlfn.XLOOKUP(A10,'Job Details'!A:A,'Job Details'!AU:AU,"Not In Job Details")) -> Pending
A11: TRIS_RH_ARCOS_Overtime_Yearly | B11: =IF(_xlfn.XLOOKUP(A11,'Job Details'!A:A,'Job Details'!I:I,"Not in schedule")=0,"Pending",_xlfn.XLOOKUP(A11,'Job Details'!A:A,'Job Details'!I:I,"Not in schedule")) -> Pending | C11: =IF(_xlfn.XLOOKUP(A11,'Job Details'!A:A,'Job Details'!AU:AU,"Job Details")=0,"Pending",_xlfn.XLOOKUP(A11,'Job Details'!A:A,'Job Details'!AU:AU,"Not In Job Details")) -> Pending
A12: TRIS_RH_Contract_Final | B12: =IF(_xlfn.XLOOKUP(A12,'Job Details'!A:A,'Job Details'!I:I,"Not in schedule")=0,"Pending",_xlfn.XLOOKUP(A12,'Job Details'!A:A,'Job Details'!I:I,"Not in schedule")) -> Pending | C12: =IF(_xlfn.XLOOKUP(A12,'Job Details'!A:A,'Job Details'!AU:AU,"Job Details")=0,"Pending",_xlfn.XLOOKUP(A12,'Job Details'!A:A,'Job Details'!AU:AU,"Not In Job Details")) -> Pending
A13: TRIS_RH_Contract_Final_010_BuildPayrollFiles_vJOB_TR | B13: =IF(_xlfn.XLOOKUP(A13,'Job Details'!A:A,'Job Details'!I:I,"Not in schedule")=0,"Pending",_xlfn.XLOOKUP(A13,'Job Details'!A:A,'Job Details'!I:I,"Not in schedule")) -> Pending | C13: =IF(_xlfn.XLOOKUP(A13,'Job Details'!A:A,'Job Details'!AU:AU,"Job Details")=0,"Pending",_xlfn.XLOOKUP(A13,'Job Details'!A:A,'Job Details'!AU:AU,"Not In Job Details")) -> Pending
... A160: TRIS_RN_monthly_single_050_MF_TR33318 | B160: =IF(_xlfn.XLOOKUP(A160,'Job Details'!A:A,'Job Details'!I:I,"Not in schedule")=0,"Pending",_xlfn.XLOOKUP(A160,'Job Details'!A:A,'Job Details'!I:I,"Not in schedule")) -> Pending | C160: =IF(_xlfn.XLOOKUP(A160,'Job Details'!A:A,'Job Details'!AU:AU,"Job Details")=0,"Pending",_xlfn.XLOOKUP(A160,'Job Details'!A:A,'Job Details'!AU:AU,"Not In Job Details")) -> Pending

Sheet Job Details
A1: Please see the bottom Notes for more info on highlighted jobs.
A2: Job Name | B2: Box | C2: Step | D2: Days | E2: Time | F2: Old process/Command | G2: Gateway URL | H2: Status | I2: New autosys | J2: Description of Job | K2: Wipro Contact | L2: New TRIS Csharp Jobs | M2: Description | N2: Job Type | O2: Box Name | P2: Owner | Q2: Machine | R2: Command | S2: Permissions | T2: JCL library | U2: JCL member | V2: Has Date Condition | W2: Start Time | X2: Run Calendar | Y2: Exclude Calendar | Z2: Alarm | AA2: Profile | AB2: Send Notification | AC2: Schedule Priority | AD2: Email Notified | AE2: Email Message | AF2: Mainframe Condtion Code | AG2: Start Mins | AH2: std out file | AI2: std err file | AJ2: FTP transfer type | AK2: FTP transfer direction | AL2: FTP local name | AM2: FTP remote name | AN2: FTP server name | AO2: FTP use ssl | AP2: FTP local user | AQ2: FTP user type | AR2: max run alarm | AS2: box terminator | AT2: term run time | AU2: Test Status
A3: TRIS_RH_ARCOS_Daily_Box | D3: su,mo,tu,we,th,fr,sa | E3: 0.5 | M3: TRIS ARCOS Daily Interface Files CHG0000000xxxxx | N3: BOX | P3: TRISBATCH@ameren | S3: gx,mx | V3: 1 | W3: 0.54166667 | Z3: 1 | AC3: 3
A4: TRIS_RH_ARCOS_Overtime_Daily | B4: TRIS_RH_ARCOS_Daily_Box | C4: 1 | F4: C:\TRISBatch\ARCOSOvertimeInterface\ARCOSOvertimeInterface.exe | L4: /api/core/payroll/v1/ARCOSHRInterface/strike/process | M4: TRIS daily ARCOS HR interface #RH#DV-HR-TR# CHG CHG0000000xxxxx | N4: CMD | O4: TRIS_RH_ARCOS_Daily_Box | P4: TRISBATCH@ameren | Q4: V_TRIS_BATCH | R4: $$TRIS_BATCHDIR\ARCOSHRInterface\ARCOSHRInterface.exe | S4: gx,mx | V4: 0 | Z4: 1 | AA4: TRIS | AB4: F | AC4: 3 | AD4: DLTRISTeam@ameren.com | AE4: TRIS_RH_ARCOS_HR_Daily FAILED. | AH4: >>$$TRIS_BATCHDIR\Logs\%AUTO_JOB_NAME%_stdout.txt | AI4: >>$$TRIS_BATCHDIR\Logs\%AUTO_JOB_NAME%_stderr.txt
A5: TRIS_RH_ARCOS_HR_Daily | B5: TRIS_RH_ARCOS_Daily_Box | C5: 2 | D5: s(TRIS_RH_ARCOS_Overtime_Daily) | F5: C:\TRISBatch\ARCOSHRInterface\ARCOSHRInterface.exe | L5: /api/core/payroll/v1/ArcosOvertimeInterface/interface | M5: TRIS daily ARCOS Overtime interface #RH#DV-HR-TR# CHG0000000xxxxx | N5: CMD | O5: TRIS_RH_ARCOS_Daily_Box | P5: TRISBATCH@ameren | Q5: V_TRIS_BATCH | R5: $$TRIS_BATCHDIR\ARCOSOvertimeInterface\ARCOSOvertimeInterface.exe | S5: gx,mx | V5: 0 | Z5: 1 | AA5: TRIS | AB5: F | AC5: 3 | AD5: DLTRISTeam@ameren.com | AE5: TRIS_RH_ARCOS_Overtime_Daily FAILED. | AH5: >>$$TRIS_BATCHDIR\Logs\%AUTO_JOB_NAME%_stdout.txt | AI5: >>$$TRIS_BATCHDIR\Logs\%AUTO_JOB_NAME%_stderr.txt
A6: TRIS_RH_ARCOS_Sched_Daily | B6: TRIS_RH_ARCOS_Daily_Box | C6: 3 | D6: s(TRIS_RH_ARCOS_HR_Daily) | F6: C:\TRISBatch\ARCOSScheduleInterface\ARCOSSchedulingInterface.exe | L6: /api/core/payroll/v1/ARCOSOvertimeWeekly/build-all-standings | M6: TRIS weekly ARCOS Build Next Standing #RN#DV-HR-TR# CHG0000000xxxxx | N6: CMD | O6: TRIS_RH_ARCOS_Weekly_Box | P6: TRISBATCH@ameren | Q6: V_TRIS_BATCH | R6: $$TRIS_BATCHDIR\ARCOSOvertimeWeeklyProcess\ARCOSOvertimeWeeklyProcess.exe | S6: gx,mx | V6: 0 | Z6: 1 | AA6: TRIS | AB6: F | AC6: 3 | AD6: DLTRISTeam@ameren.com | AE6: TRIS_RH_ARCOS_Overtime_Weekly FAILED. | AH6: >>$$TRIS_BATCHDIR\Logs\%AUTO_JOB_NAME%_stdout.txt | AI6: >>$$TRIS_BATCHDIR\Logs\%AUTO_JOB_NAME%_stderr.txt
A7: TRIS_RH_ARCOS_SFTP_Daily | B7: TRIS_RH_ARCOS_Daily_Box | C7: 4 | D7: s(TRIS_RH_ARCOS_Sched_Daily) | L7: /api/core/payroll/v1/ARCOSOvertimeYearly/rezero-standings | M7: TRIS ARCOS Yearly -- Re-Zero Standings -- Jim Barnett 314-630-7969 #RN#DV-HR-TR# CHG0000000xxxxx | N7: CMD | O7: TRIS_RH_ARCOS_Yearly_Box | P7: TRISBATCH@ameren | Q7: V_TRIS_BATCH | R7: $$TRIS_BATCHDIR\ARCOSOvertimeYearlyProcess\ARCOSOvertimeYearlyProcess.exe | S7: gx,mx | V7: 0 | Z7: 1 | AA7: TRIS | AB7: F | AC7: 3 | AD7: DLTRISTeam@ameren.com | AE7: TRIS_RH_ARCOS_Overtime_Yearly FAILED. | AH7: >>$$TRIS_BATCHDIR\Logs\%AUTO_JOB_NAME%_stdout.txt | AI7: >>$$TRIS_BATCHDIR\Logs\%AUTO_JOB_NAME%_stderr.txt
A8: TRIS_RH_ARCOS_Delete_files | B8: TRIS_RH_ARCOS_Daily_Box | C8: 5 | D8: s(TRIS_RH_ARCOS_SFTP_Daily) | F8: $$TRIS_BATCHDIR\ARCOSDeleteFiles\ARCOSDeleteFiles.exe | L8: /api/core/payroll/v1/ARCOSSchedulingInterface/build-schedule-file | M8: TRIS daily ARCOS Schedule interface #RH#DV-HR-TR# CHG CHG0000000xxxxx | N8: CMD | O8: TRIS_RH_ARCOS_Daily_Box | P8: TRISBATCH@ameren | Q8: V_TRIS_BATCH | R8: $$TRIS_BATCHDIR\ARCOSScheduleInterface\ARCOSSchedulingInterface.exe | S8: gx,mx | V8: 0 | Z8: 1 | AA8: TRIS | AB8: F | AC8: 3 | AD8: DLTRISTeam@ameren.com | AE8: TRIS_RH_ARCOS_Sched_Daily FAILED. | AH8: >>$$TRIS_BATCHDIR\Logs\%AUTO_JOB_NAME%_stdout.txt | AI8: >>$$TRIS_BATCHDIR\Logs\%AUTO_JOB_NAME%_stderr.txt
A9: TRIS_RH_ARCOS_Weekly_Box | D9: we | E9: 0.25 | L9: /api/core/payroll/v1/ARCOSOvertimeWeekly/build-all-standings | M9: TRIS ARCOS Weekly Create next Standing CHG0000000xxxxx | N9: BOX | P9: TRISBATCH@ameren | S9: gx,mx | V9: 1 | W9: 0.25 | Z9: 1 | AC9: 3
A10: TRIS_RH_ARCOS_Overtime_Weekly | B10: TRIS_RH_ARCOS_Weekly_Box | C10: 1 | F10: C:\TRISBatch\ARCOSOvertimeWeeklyProcess\ARCOSOvertimeWeeklyProcess.exe | L10: /api/core/payroll/v1/ARCOSOvertimeYearly/rezero-standings | M10: TRIS ARCOS Yearly -- Re-Zero Standings -- Jim Barnett 314-630-7969 CHG0000000xxxxx | N10: BOX | P10: TRISBATCH@ameren | S10: gx,mx | V10: 1 | W10: 0.27083333 | Z10: 1 | AC10: 3
A11: TRIS_RH_ARCOS_Yearly_Box | D11: AM_1st_WED_JAN | E11: 0.27083333 | M11: This runs the TRIS portion of the contract payroll | N11: BOX | P11: TRISBATCH@ameren | S11: gx,mx | V11: 0 | Z11: 1 | AC11: 3
A12: TRIS_RH_ARCOS_Overtime_Yearly | B12: TRIS_RH_ARCOS_Yearly_Box | C12: 1 | F12: C:\TRISBatch\ARCOSOvertimeYearlyProcess\ARCOSOvertimeYearlyProcess.exe | L12: /api/core/notification/v1/jobs/buildFile | M12: Build File for DB2 Load of VJOB_TR #RH#DV-HR-TR# CHG0000000xxxxx | N12: CMD | O12: TRIS_RH_Contract_Final | P12: TRISBATCH@ameren | Q12: V_TRIS_BATCH | R12: $$TRIS_BATCHDIR\BuildDB2LoadFiles\BuildVjob\BuildVjob.exe | S12: gx,mx | V12: 0 | Z12: 1 | AA12: TRIS | AB12: F | AC12: 3 | AD12: DLTRISTeam@ameren.com | AE12: TRIS_RH_Contract_Final_010_BuildPayrollFiles_vJOB_TR FAILED | AH12: >>$$TRIS_BATCHDIR\Logs\%AUTO_JOB_NAME%_stdout.txt | AI12: >>$$TRIS_BATCHDIR\Logs\%AUTO_JOB_NAME%_stderr.txt
A13: TRIS_RH_Contract_Final | D13: On demand | L13: /api/core/notification/v1/departments/buildFile | M13: Build File for DB2 Load of VDEPT_TBL_TR #RH#DV-HR-TR# CHG0000000xxxxx | N13: CMD | O13: TRIS_RH_Contract_Final | P13: TRISBATCH@ameren | Q13: V_TRIS_BATCH | R13: $$TRIS_BATCHDIR\BuildDB2LoadFiles\BuildVdept\BuildVdept.exe | S13: gx,mx | V13: 0 | Z13: 1 | AA13: TRIS | AB13: F | AC13: 3 | AD13: DLTRISTeam@ameren.com | AE13: TRIS_RH_Contract_Final_020_BuildPayrollFiles_vDEPT_TBL_TR FAILED | AH13: >>$$TRIS_BATCHDIR\Logs\%AUTO_JOB_NAME%_stdout.txt | AI13: >>$$TRIS_BATCHDIR\Logs\%AUTO_JOB_NAME%_stderr.txt
A14: TRIS_RH_Contract_Final_010_BuildPayrollFiles_vJOB_TR | B14: TRIS_RH_Contract_Final | C14: 1 | F14: C:\TRISBatch\BuildDB2LoadFiles\BuildVjob\BuildVjob.exe | L14: /api/core/notification/v1/jobcodes/buildFile | M14: Build File for DB2 Load of VJOBCODE_TBL_TR #RH#DV-HR-TR# CHG0000000xxxxx | N14: CMD | O14: TRIS_RH_Contract_Final | P14: TRISBATCH@ameren | Q14: V_TRIS_BATCH | R14: $$TRIS_BATCHDIR\BuildDB2LoadFiles\BuildVjobcode\BuildVjobcode.exe | S14: gx,mx | V14: 0 | Z14: 1 | AA14: TRIS | AB14: F | AC14: 3 | AD14: DLTRISTeam@ameren.com | AE14: TRIS_RH_Contract_Final_030_BuildPayrollFiles_vJOBCODE_TBL_TR FAILED | AH14: >>$$TRIS_BATCHDIR\Logs\%AUTO_JOB_NAME%_stdout.txt | AI14: >>$$TRIS_BATCHDIR\Logs\%AUTO_JOB_NAME%_stderr.txt
A15: TRIS_RH_Contract_Final_020_BuildPayrollFiles_vDEPT_TBL_TR | B15: TRIS_RH_Contract_Final | C15: 2 | D15: s(TRIS_RH_Contract_Final_010_BuildPayrollFiles_vJOB_TR) | F15: C:\TRISBatch\BuildDB2LoadFiles\BuildVdept\BuildVdept.exe | L15: /api/core/common/v1/JobSalaryStep/generate-file | M15: Build File for DB2 Load of VSAL_STEP_TBL_TR #RH#DV-HR-TR# CHG0000000xxxxx | N15: CMD | O15: TRIS_RH_Contract_Final | P15: TRISBATCH@ameren | Q15: V_TRIS_BATCH | R15: $$TRIS_BATCHDIR\BuildDB2LoadFiles\BuildVsalarystep\BuildVsalarystep.exe | S15: gx,mx | V15: 0 | Z15: 1 | AA15: TRIS | AB15: F | AC15: 3 | AD15: DLTRISTeam@ameren.com | AE15: TRIS_RH_Contract_Final_040_BuildPayrollFiles_vSAL_STEP_TR FAILED | AH15: >>$$TRIS_BATCHDIR\Logs\%AUTO_JOB_NAME%_stdout.txt | AI15: >>$$TRIS_BATCHDIR\Logs\%AUTO_JOB_NAME%_stderr.txt
A16: TRIS_RH_Contract_Final_030_BuildPayrollFiles_vJOBCODE_TR | B16: TRIS_RH_Contract_Final | C16: 3 | D16: s(TRIS_RH_Contract_Final_020_BuildPayrollFiles_vDEPT_TBL_TR) | F16: C:\TRISBatch\BuildDB2LoadFiles\BuildVjobcode\BuildVjobcode.exe | L16: NA | M16: FTP of file to load into VJOB_TR load #RH#DV-HR-TR# CHG0000000xxxxx | N16: FTP | O16: TRIS_RH_Contract_Final | P16: ASYSFTPP@SYSC | Q16: V_TRIS_BATCH | S16: gx,mx | V16: 0 | Z16: 1 | AB16: F | AC16: 3 | AD16: DLTRISTeam@ameren.com | AE16: TRIS_RH_Contract_Final_050_BuildPayrollFiles_FTP_vJOB_TR FAILED | AJ16: A | AK16: UPLOAD | AL16: $$TRIS_BATCHDIR\\DB2LoadFiles\\VJOB-TR-EXTRACT.txt | AM16: ITP.DATA.JOB | AN16: SYSC.ameren.com | AO16: 0 | AP16: TRISBATCH@ameren | AQ16: Simple
A17: TRIS_RH_Contract_Final_040_BuildPayrollFiles_vSAL_STEP_TR | B17: TRIS_RH_Contract_Final | C17: 4 | D17: S(TRIS_RH_Contract_Final_030_BuildPayrollFiles_vJOBCODE_TR ) | F17: C:\TRISBatch\BuildDB2LoadFiles\BuildVsalarystep\BuildVsalarystep.exe | L17: NA | M17: FTP of file to load into VDEPT_TBL_TR load #RH#DV-HR-TR# CHG0000000xxxxx | N17: FTP | O17: TRIS_RH_Contract_Final | P17: ASYSFTPP@SYSC | Q17: V_TRIS_BATCH | S17: gx,mx | V17: 0 | Z17: 1 | AB17: F | AC17: 3 | AD17: DLTRISTeam@ameren.com | AE17: TRIS_RH_Contract_Final_060_BuildPayrollFiles_FTP_vDEPT_TR FAILED | AJ17: A | AK17: UPLOAD | AL17: $$TRIS_BATCHDIR\\DB2LoadFiles\\VDEPT-TBL-TR-EXTRACT.txt | AM17: ITP.DATA.DEPT | AN17: SYSC.ameren.com | AO17: 0 | AP17: TRISBATCH@ameren | AQ17: Simple
A18: TRIS_RH_Contract_Final_050_BuildPayrollFiles_FTP_vJOB_TR | B18: TRIS_RH_Contract_Final | C18: 5 | D18: S(TRIS_RH_Contract_Final_040_BuildPayrollFiles_vSAL_STEP_TR) | L18: NA | M18: FTP of file to load into VJOBCODE_TBL_TR load #RH#DV-HR-TR# CHG0000000xxxxx | N18: FTP | O18: TRIS_RH_Contract_Final | P18: ASYSFTPP@SYSC | Q18: V_TRIS_BATCH | S18: gx,mx | V18: 0 | Z18: 1 | AB18: F | AC18: 3 | AD18: DLTRISTeam@ameren.com | AE18: TRIS_RH_Contract_Final_070_BuildPayrollFiles_FTP_vJOBCODE FAILED | AJ18: A | AK18: UPLOAD | AL18: $$TRIS_BATCHDIR\\DB2LoadFiles\\VJOBCODE-TBL-TR-EXTRACT.txt | AM18: ITP.DATA.JOBCODE | AN18: SYSC.ameren.com | AO18: 0 | AP18: TRISBATCH@ameren | AQ18: Simple
A19: TRIS_RH_Contract_Final_060_BuildPayrollFiles_FTP_vDEPT_TR | B19: TRIS_RH_Contract_Final | C19: 6 | D19: S(TRIS_RH_Contract_Final_050_BuildPayrollFiles_FTP_vJOB_TR) | L19: NA | M19: FTP of file to load into VSAL_STEP_TBL_TR load #RH#DV-HR-TR# CHG0000000xxxxx | N19: FTP | O19: TRIS_RH_Contract_Final | P19: ASYSFTPP@SYSC | Q19: V_TRIS_BATCH | S19: gx,mx | V19: 0 | Z19: 1 | AB19: F | AC19: 3 | AD19: DLTRISTeam@ameren.com | AE19: TRIS_RH_Contract_Final_080_BuildPayrollFiles_FTP_vSAL FAILED | AJ19: A | AK19: UPLOAD | AL19: $$TRIS_BATCHDIR\\DB2LoadFiles\\VSAL-STEP-TBL-TR-EXTRACT.txt | AM19: ITP.DATA.SAL.STP | AN19: SYSC.ameren.com | AO19: 0 | AP19: TRISBATCH@ameren | AQ19: Simple
A20: TRIS_RH_Contract_Final_070_BuildPayrollFiles_FTP_vJOBCODE | B20: TRIS_RH_Contract_Final | C20: 7 | D20: S(TRIS_RH_Contract_Final_060_BuildPayrollFiles_FTP_vDEPT_TR) | L20: Cobol | M20: Loads the FTP files that contained HR data for Payroll into DB2 Tables #RH#DV-HR-TR# CHG0000000xxxxx | N20: ZOS | O20: TRIS_RH_Contract_Final | P20: ESPAE | Q20: V_TRIS_TRJobs2MF | T20: CF.STARTPDS | U20: AR13895 | V20: 0 | Z20: 1 | AB20: F | AD20: DLTRISTeam@ameren.com | AE20: TRIS_RH_Contract_Final_200_MF_AR13895 FAILED. Loads the FTP files that contained HR data for Payroll into DB2 Tables | AF20: action=STOP,rc=4\:4095,result=FAILURE
A21: TRIS_RH_Contract_Final_080_BuildPayrollFiles_FTP_vSAL | B21: TRIS_RH_Contract_Final | C21: 8 | D21: S(TRIS_RH_Contract_Final_050_BuildPayrollFiles_FTP_vJOB_TR) | M21: Fills tables for view VJOB_TR_EFF which allows the HR History records to have a start and end date versus just an effective date. #RH#DV-HR-TR# CHG00000000xxxx | N21: CMD | O21: TRIS_RH_Contract_Final | P21: TRISBATCH@ameren | Q21: V_TRIS_BATCH | R21: $$TRIS_BATCHDIR\PSJobViewRefresh\PS2TRIS.exe | S21: gx,mx | V21: 0 | Z21: 1 | AA21: TRIS | AB21: F | AC21: 3 | AD21: DLTRISTeam@ameren.com | AE21: TRIS_RH_Contract_Final_300_Build_HR_History_View FAILED. Fills tables for view VJOB_TR_EFF which allows the HR History records to have a start and end date versus just an effective date. Look in \C\\TRISBatch\\Logs\ on server | AH21: >>$$TRIS_BATCHDIR\Logs\%AUTO_JOB_NAME%_stdout.txt | AI21: >>$$TRIS_BATCHDIR\Logs\%AUTO_JOB_NAME%_stderr.txt
A22: TRIS_RH_Contract_Final_200_MF_AR13895 | B22: TRIS_RH_Contract_Final | C22: 9 | D22: S(TRIS_RH_Contract_Final_080_BuildPayrollFiles_FTP_Vsal) | F22: TR33003: IEBGENERs to manage files and Utilities to load tables | L22: Cobol | M22: Mainframe Contract Payroll processing that produces Payroll file that is used in TRIS_RH_Contract_Final_550_Send_ToPayroll to build a JSON request to send to Workday #RH#DV-HR-TR# CHG0000000xxxxx | N22: ZOS | O22: TRIS_RH_Contract_Final | P22: ESPAE | Q22: V_TRIS_TRJobs2MF | T22: UE.STARTPDS | U22: TR33200 | V22: 0 | Z22: 1 | AB22: F | AD22: DLTRISTeam@ameren.com | AE22: TRIS_RH_Contract_Final_410_MF_TR33200 FAILED. Mainframe Contract Payroll processing that produces Payroll file that is used in TRIS_RH_Contract_Final_550_Send_ToPayroll to build a JSON request to send to Workday | AF22: action=STOP,rc=1\:4095,result=FAILURE
A23: TRIS_RH_Contract_Final_300_Build_HR_History_View | B23: TRIS_RH_Contract_Final | C23: 10 | D23: s(TRIS_RH_Contract_Final_200_MF_AR13895) | F23: C:\TRISBatch\PSJobViewRefresh\PS2TRIS.exe | L23: Cobol | M23: FTPs Mainframe Payroll File built in TRIS_RH_Contract_Final_410_MF_TR33200 to Autosys server #RH#DV-HR-TR# CHG0000000xxxxx | N23: ZOS | O23: TRIS_RH_Contract_Final | P23: ESPAE | Q23: V_TRIS_TRJobs2MF | T23: CF.STARTPDS | U23: AR13687 | V23: 0 | Z23: 1 | AB23: F | AD23: DLTRISTeam@ameren.com | AE23: TRIS_RH_Contract_Final_420_MF_AR13687 FAILED. FTPs Mainframe Payroll File built in TRIS_RH_Contract_Final_410_MF_TR33200 to Autosys server | AF23: action=STOP,rc=1\:4095,result=FAILURE
A24: TRIS_RH_Contract_Final_410_MF_TR33200 | B24: TRIS_RH_Contract_Final | C24: 11 | D24: s(TRIS_RH_Contract_Final_300_Build_HR_History_View) | F24: TR33200: TR001-Extract actual time and adjustments TR039-Missing time report (33729) TR051-Allowed time records TR052-Split extract file for sick leave TR003-Allowed time (actual time) processing TR050-Create sick leave detail TR021-Adjustment processing TR003C-CIPS Allowed time (actual time) processing (Report 33708) TR050-Create CIPS sick leave detail TR021C CIPS Adjustment processing TR105-Load sick leave detail and banks work tables TR106-Process sick leave TR131-Sick leave LTD messages TR108-Sick leave messages report (Report TR33801) TR004-Payroll earnings proof (Report 33700) TR005-Payroll deviations (Rpeort 33703) TR060-Paysheet prep TR061-Print repor 33781 paysheet memo report TR033-Unlock departments TR037-Update final cycle number | G24: https://rxvavgtcv7.execute-api.us-east-1.amazonaws.com/dev/tr-33200 | I24: TR_RN_ContractPayroll_TR33200_Trigger_Box | L24: Cobol | M24: Copies Mainframe payroll file on the Autosys server to the RIS folder on the Corporate share drive #RH#DV-HR-TR# CHG0000000xxxxx | N24: CMD | O24: TRIS_RH_Contract_Final | P24: TRISBATCH@ameren | Q24: V_TRIS_MFFTP | R24: %FTPDir2%\Exec\copy_file.bat %FTPDir%\tr_payroll_cont.txt \\corp.dir.ameren.com\dfs\Orgdrv\TRIS\MKS\tr_payroll_cont.txt | S24: gx,mx | V24: 0 | Z24: 1 | AA24: TRIS | AB24: F | AC24: 3 | AD24: DLTRISTeam@ameren.com | AE24: TRIS_RH_Contract_Final_530_Send_Copy_PayrollFile JOB FAILED. Copies Mainframe payroll file on the Autosys server to the RIS folder on the Corporate share drive | AH24: %FTPDir2%\Logs\Payroll_stdout.txt | AI24: %FTPDir2%\Logs\Payroll_stderr.txt
A25: TRIS_RH_Contract_Final_420_MF_AR13687 | B25: TRIS_RH_Contract_Final | C25: 12a | D25: s(TRIS_RH_Contract_Final_410_MF_TR33200) | F25: TR33007(Sends (FTP) contract payroll file to be processed to workday payroll) | L25: Cobol | M25: Moves Mainframe Payroll file from the TRIS folder on the Corporate share drive to the TRIS Server (V_TRIS_BATCH) #RH#DV-HR-TR# CHG0000000xxxxx | N25: CMD | O25: TRIS_RH_Contract_Final | P25: TRISBATCH@ameren | Q25: V_TRIS_BATCH | R25: $$TRIS_BATCHDIR\MoveMainframeFiles\MovePayrollFile\MovePayrollFile.exe | S25: gx,mx | V25: 0 | Z25: 1 | AA25: TRIS | AB25: F | AC25: 3 | AD25: DLTRISTeam@ameren.com | AE25: TRIS_RH_Contract_Final_540_Send_Move_PayrollFile FAILED. Moves Mainframe Payroll file from the TRIS folder on the Corporate share drive to the TRIS Server (V_TRIS_BATCH) | AH25: >>$$TRIS_BATCHDIR\Logs\%AUTO_JOB_NAME%_stdout.txt | AI25: >>$$TRIS_BATCHDIR\Logs\%AUTO_JOB_NAME%_stderr.txt
A26: TRIS_RH_Contract_Final_530_Send_Copy_PayrollFile | B26: TRIS_RH_Contract_Final | C26: 13a | D26: s(TRIS_RH_Contract_Final_420_MF_AR13687) | F26: %FTPDir2%\Exec\copy_file.bat %FTPDir%\tr_payroll_cont.txt \\corp.dir.ameren.com\dfs\Orgdrv\TRIS\MKS\tr_payroll_cont.txt | L26: /api/core/notification/v1/WorkdayPayroll/execute | M26: Send Payroll to Workday #RH#DV-HR-TR# CHG0000000xxxxx | N26: CMD | O26: TRIS_RH_Contract_Final | P26: TRISBATCH@ameren | Q26: V_TRIS_BATCH | R26: $$TRIS_BATCHDIR\WorkdayPayrollInterface\WorkdayPayrollInterface.exe | S26: gx,mx | V26: 0 | Z26: 1 | AA26: TRIS | AB26: F | AC26: 3 | AD26: DLTRISTeam@ameren.com | AE26: TRIS_RH_Contract_Final_550_Send_ToPayroll FAILED | AH26: >>$$TRIS_BATCHDIR\Logs\%AUTO_JOB_NAME%_stdout.txt | AI26: >>$$TRIS_BATCHDIR\Logs\%AUTO_JOB_NAME%_stderr.txt
A27: TRIS_RH_Contract_Final_540_Send_Move_PayrollFile | B27: TRIS_RH_Contract_Final | C27: 14a | D27: s(TRIS_RH_Contract_Final_530_Send_Copy_PayrollFile) | F27: C:\TRISBatch\MoveMainframeFiles\MovePayrollFile\MovePayrollFile.exe | L27: Cobol | M27: Updates the sick leave banks to be viewed in TRIS after the Contract Final Job completes TRIS_RH_Contract_Final_210_MF_TR33200 #RH#DV-HR-TR# CHG0000000xxxxx (dynamic sick leave processing) | N27: ZOS | O27: TRIS_RH_Contract_Final | P27: ESPAE | Q27: V_TRIS_TRJobs2MF | T27: UE.STARTPDS | U27: TR33206 | V27: 0 | Z27: 1 | AB27: F | AD27: DLTRISTeam@ameren.com | AE27: TRIS_RH_Contract_Final_600_MF_TR33206 FAILED. Updates the sick leave banks to be viewed in TRIS after the Contract Final Job completes TRIS_RH_Contract_Final_210_MF_TR33200 | AF27: action=STOP,rc=1\:4095,result=FAILURE
A28: TRIS_RH_Contract_Final_550_Send_ToPayroll | B28: TRIS_RH_Contract_Final | C28: 15a | D28: s(TRIS_RH_Contract_Final_540_Send_Move_PayrollFile) | F28: C:\TRISBatch\WorkdayPayrollInterface\WorkdayPayrollInterface.exe | L28: Cobol | M28: Contract Preliminary Job on Request #RH#DV-HR-TR# CHG0000000xxxxx | N28: ZOS | P28: ESPAE | Q28: V_TRIS_TRJobs2MF | T28: UE.STARTPDS | U28: TR33103N | V28: 0 | Z28: 1 | AB28: F | AD28: DLTRISTeam@ameren.com | AE28: TRIS_RH_Contract_Preliminary_OnRequest_MF_TR33103N FAILED. Contract Preliminary Job on Request | AF28: action=STOP,rc=1\:4095,result=FAILURE
A29: TRIS_RH_Contract_Final_600_MF_TR33206 | B29: TRIS_RH_Contract_Final | C29: 12b | D29: s(TRIS_RH_Contract_Final_410_MF_TR33200) | F29: TR33206: TR109-Update sick leave banks with current balances TR107-Update sick leave detail and banks from work tables TR077-Sick leave detail report TR042-CIPS/Gen local 702 sick leave reports TR029-Report 33701-Reported Time Adjustments TR026-Split Exception codes for allowed time TR135-Allowed time detail table update TR136-Relief Hours table update TR137-Hours worked of relief reports TR111-Temporary Referral worker (TRW) report TR134-Union OA 12 hour shift sick leave certiification (day 4 only) | G29: https://rxvavgtcv7.execute-api.us-east-1.amazonaws.com/dev/tr-33206 | I29: TR_RN_ContractPayroll_TR33206_Trigger_Box | L29: /api/core/notification/v1/departments/common/buildFile | M29: Builds File for DB2 Load of TAR_COMN_DEPT_TBL. #RH#DV-HR-TR# CHG0000000xxxxx | N29: CMD | O29: TRIS_RH_dailyBox | P29: TRISBATCH@ameren | Q29: V_TRIS_BATCH | R29: $$TRIS_BATCHDIR\BuildDB2LoadFiles\BuildCommonDepartment\BuildCommonDepartment.exe | S29: gx,mx | V29: 0 | Z29: 1 | AA29: TRIS | AB29: F | AC29: 3 | AD29: DLTRISTeam@ameren.com | AE29: TRIS_RH_daily_010_BuildCommon_Department FAILED. Builds File for DB2 Load of TAR_COMN_DEPT_TBL. Look in \C\\TRISBatch\\Logs\ on server | AH29: >>$$TRIS_BATCHDIR\Logs\%AUTO_JOB_NAME%_stdout.txt | AI29: >>$$TRIS_BATCHDIR\Logs\%AUTO_JOB_NAME%_stderr.txt
A30: TRIS_RH_Contract_Preliminary_OnRequest_MF_TR33103N | D30: Failure of mainframe job | F30: TR33103: TR033-Lock departments on the last prelim run before final TR001-Extract actual time and adjustments TR039-Missing time report (33729) TR051-Allowed time records TR052-Split extract file for sick leave TR003-Allowed time (actual time) processing TR050-Create sick leave detail TR021-Adjustment processing TR117-702 check previous year fmla TR003C-CIPS Allowed time (actual time) processing TR050-Create sick leave detail TR021C CIPS Adjustment processing TR104-Sick leave certification TR115-Sick leave FMLA updates TR105-Load sick leave detail and banks work tables TR106-Process sick leave TR108-Sick leave messages report (Report TR33801) TR004-Payroll earnings proof (Report 33700) TR005-Payroll deviations (Rpeort 33703) TR077-Sick leave detail report TR029-Report 33701-Reported Time Adjustments (33701) | G30: https://rxvavgtcv7.execute-api.us-east-1.amazonaws.com/dev/tr-33103n | I30: TR_RN_ContractPayroll_TR33103N_Trigger_Box | L30: /api/core/notification/v1/employees/buildFile | M30: Builds File for DB2 Load of TAR_COMN_EMP_TBL and Builds for DB2 Load of THRDB_EMPLOYEE_TBL #RH#DV-HR-TR# CHG0000000xxxxx | N30: CMD | O30: TRIS_RH_dailyBox | P30: TRISBATCH@ameren | Q30: V_TRIS_BATCH | R30: $$TRIS_BATCHDIR\BuildDB2LoadFiles\BuildCommonEmployeeFile\BuildCommonEmployeeFile.exe | S30: gx,mx | V30: 0 | Z30: 1 | AA30: TRIS | AB30: F | AC30: 3 | AD30: DLTRISTeam@ameren.com | AE30: TRIS_RH_daily_020_BuildCommon_Employee FAILED. Builds File for DB2 Load of TAR_COMN_EMP_TBL and Builds for DB2 Load of THRDB_EMPLOYEE_TBL. Look in \C\\TRISBatch\\Logs\ on server | AH30: >>$$TRIS_BATCHDIR\Logs\%AUTO_JOB_NAME%_stdout.txt | AI30: >>$$TRIS_BATCHDIR\Logs\%AUTO_JOB_NAME%_stderr.txt
A31: TRIS_RH_dailyBox | L31: NA | M31: FTP of file to load into TAR_COMN_DEPT_TBL. #RH#DV-HR-TR# CHG0000000xxxxx | N31: FTP | O31: TRIS_RH_dailyBox | P31: ASYSFTPP@SYSC | Q31: V_TRIS_BATCH | S31: gx,mx | V31: 0 | Z31: 1 | AB31: F | AC31: 3 | AD31: DLTRISTeam@ameren.com | AE31: TRIS_RH_daily_030_BuildCommon_FTP_Department FAILED. FTP of file to load into TAR_COMN_DEPT_TBL. | AJ31: A | AK31: UPLOAD | AL31: $$TRIS_BATCHDIR\\DB2LoadFiles\\CommonDepartment-EXTRACT.txt | AM31: ITP.DATA.GDG.DEPT.EXTRT | AN31: SYSC.ameren.com | AO31: 0 | AP31: TRISBATCH@ameren | AQ31: Simple
A32: TRIS_RH_daily_010_BuildCommon_Department | B32: TRIS_RH_dailyBox | C32: 1 | D32: mo,tu,we,th,fr,sa | E32: 0.041666667 | F32: C:\TRISBatch\BuildDB2LoadFiles\BuildCommonDepartment\BuildCommonDepartment.exe | L32: NA | M32: FTP a file to load into TAR_COMN_EMPL_TBL. #RH#DV-HR-TR# CHG0000000xxxxx | N32: FTP | O32: TRIS_RH_dailyBox | P32: ASYSFTPP@SYSC | Q32: V_TRIS_BATCH | S32: gx,mx | V32: 0 | Z32: 1 | AB32: F | AC32: 3 | AD32: DLTRISTeam@ameren.com | AE32: TRIS_RH_daily_040_BuildCommon_FTP_Employee FAILED. FTP a file to load into TAR_COMN_EMPL_TBL | AJ32: A | AK32: UPLOAD | AL32: $$TRIS_BATCHDIR\\DB2LoadFiles\\COMNEMPL-EXTRACT.txt | AM32: ITP.DATA.GDG.EMPL.EXTRT | AN32: SYSC.ameren.com | AO32: 0 | AP32: TRISBATCH@ameren | AQ32: Simple
A33: TRIS_RH_daily_020_BuildCommon_Employee | B33: TRIS_RH_dailyBox | C33: 2 | D33: s(TRIS_RH_daily_010_BuildCommon_Department) | F33: C:\TRISBatch\BuildDB2LoadFiles\BuildCommonEmployeeFile\BuildCommonEmployeeFile.exe | L33: NA | M33: FTP a File for DB2 Load of THRDB_EMPLOYEE_TBL #RH#DV-HR-TR# CHG0000000xxxxx | N33: FTP | O33: TRIS_RH_dailyBox | P33: ASYSFTPP@SYSC | Q33: V_TRIS_BATCH | S33: gx,mx | V33: 0 | Z33: 1 | AB33: F | AC33: 3 | AD33: DLTRISTeam@ameren.com | AE33: TRIS_RH_daily_050_BuildCommon_FTP_THRDBEmployee FAILED. FTP a File for DB2 Load of THRDB_EMPLOYEE_TBL | AJ33: A | AK33: UPLOAD | AL33: $$TRIS_BATCHDIR\\DB2LoadFiles\\THRDB-EMPLOYEE-EXTRACT.txt | AM33: ITP.DATA.GDG.EMPL.DB2 | AN33: SYSC.ameren.com | AO33: 0 | AP33: TRISBATCH@ameren | AQ33: Simple
A34: TRIS_RH_daily_030_BuildCommon_FTP_Department | B34: TRIS_RH_dailyBox | C34: 3 | D34: s(TRIS_RH_daily_020_BuildCommon_Employee | L34: /api/core/notification/v1/build/associations/buildFile | M34: Builds File for maintaining the TTR_ASSOCIATIONS table in mainframe job UE.STARTPDS(TR33107N). #RH#DV-HR-TR# CHG0000000xxxxx | N34: CMD | O34: TRIS_RH_dailyBox | P34: TRISBATCH@ameren | Q34: V_TRIS_BATCH | R34: $$TRIS_BATCHDIR\BuildDB2LoadFiles\BuildAssociations\BuildAssociations.exe | S34: gx,mx | V34: 0 | Z34: 1 | AA34: TRIS | AB34: F | AC34: 3 | AD34: DLTRISTeam@ameren.com | AE34: TRIS_RH_daily_070_BuildCommon_Associations FAILED. Builds File for maintaining the TTR_ASSOCIATIONS table in mainframe job UE.STARTPDS(TR33107N). Look in \C\\TRISBatch\\Logs\ on server | AH34: >>$$TRIS_BATCHDIR\Logs\%AUTO_JOB_NAME%_stdout.txt | AI34: >>$$TRIS_BATCHDIR\Logs\%AUTO_JOB_NAME%_stderr.txt
A35: TRIS_RH_daily_040_BuildCommon_FTP_Employee | B35: TRIS_RH_dailyBox | C35: 4 | D35: s(TRIS_RH_daily_030_BuildCommon_FTP_Department | L35: NA | M35: FTP a file to process in UE.STARTPDS(TR33107N). #RH#DV-HR-TR# CHG0000000xxxxx | N35: FTP | O35: TRIS_RH_dailyBox | P35: ASYSFTPP@SYSC | Q35: V_TRIS_BATCH | S35: gx,mx | V35: 0 | Z35: 1 | AB35: F | AC35: 3 | AD35: DLTRISTeam@ameren.com | AE35: TRIS_RH_daily_080_BuildCommon_FTP_Associations FAILED. FTP a file to process in UE.STARTPDS(TR33107N). | AJ35: A | AK35: UPLOAD | AL35: $$TRIS_BATCHDIR\\DB2LoadFiles\\TTR-ASSOCIATIONS-EXTRACT.txt | AM35: ITP.DATA..DPTTABLE | AN35: SYSC.ameren.com | AO35: 0 | AP35: TRISBATCH@ameren | AQ35: Simple
A36: TRIS_RH_daily_050_BuildCommon_FTP_THRDBEmployee | B36: TRIS_RH_dailyBox | C36: 5 | D36: s(TRIS_RH_daily_040_BuildCommon_FTP_Employee | L36: /api/core/notification/v1/jobs/buildFile | M36: Build File for DB2 Load of VJOB_TR #RH#DV-HR-TR# CHG0000000xxxxx | N36: CMD | O36: TRIS_RH_dailyBox | P36: TRISBATCH@ameren | Q36: V_TRIS_BATCH | R36: $$TRIS_BATCHDIR\BuildDB2LoadFiles\BuildVjob\BuildVjob.exe | S36: gx,mx | V36: 0 | Z36: 1 | AA36: TRIS | AB36: F | AC36: 3 | AD36: DLTRISTeam@ameren.com | AE36: TRIS_RH_daily_100_BuildPayrollFiles_vJOB_TR FAILED. Build File for DB2 Load of VJOB_TR. Look in \C\\TRISBatch\\Logs\ on server | AH36: >>$$TRIS_BATCHDIR\Logs\%AUTO_JOB_NAME%_stdout.txt | AI36: >>$$TRIS_BATCHDIR\Logs\%AUTO_JOB_NAME%_stderr.txt
A37: TRIS_RH_daily_070_BuildCommon_Associations | B37: TRIS_RH_dailyBox | C37: 6 | D37: s(TRIS_RH_daily_050_BuildCommon_FTP_THRDBEmployee | F37: C:\TRISBatch\BuildDB2LoadFiles\BuildAssociations\BuildAssociations.exe | L37: /api/core/notification/v1/departments/buildFile | M37: Build File for DB2 Load of VDEPT_TBL_TR #RH#DV-HR-TR# CHG0000000xxxxx | N37: CMD | O37: TRIS_RH_dailyBox | P37: TRISBATCH@ameren | Q37: V_TRIS_BATCH | R37: $$TRIS_BATCHDIR\BuildDB2LoadFiles\BuildVdept\BuildVdept.exe | S37: gx,mx | V37: 0 | Z37: 1 | AA37: TRIS | AB37: F | AC37: 3 | AD37: DLTRISTeam@ameren.com | AE37: TRIS_RH_daily_110_BuildPayrollFiles_vDEPT_TBL_TR FAILED. Build File for DB2 Load of VDEPT_TBL_TR. Look in \C\\TRISBatch\\Logs\ on server | AH37: >>$$TRIS_BATCHDIR\Logs\%AUTO_JOB_NAME%_stdout.txt | AI37: >>$$TRIS_BATCHDIR\Logs\%AUTO_JOB_NAME%_stderr.txt
A38: TRIS_RH_daily_080_BuildCommon_FTP_Associations | B38: TRIS_RH_dailyBox | C38: 7 | D38: s(TRIS_RH_daily_070_BuildCommon_Associations | L38: /api/core/notification/v1/jobcodes/buildFile | M38: Build File for DB2 Load of VJOBCODE_TBL_TR #RH#DV-HR-TR# CHG0000000xxxxx | N38: CMD | O38: TRIS_RH_dailyBox | P38: TRISBATCH@ameren | Q38: V_TRIS_BATCH | R38: $$TRIS_BATCHDIR\BuildDB2LoadFiles\BuildVjobcode\BuildVjobcode.exe | S38: gx,mx | V38: 0 | Z38: 1 | AA38: TRIS | AB38: F | AC38: 3 | AD38: DLTRISTeam@ameren.com | AE38: TRIS_RH_daily_120_BuildPayrollFiles_vJOBCODE_TBL_TR FAILED. Build File for DB2 Load of VJOBCODE_TBL_TR. Look in \C\\TRISBatch\\Logs\ on server | AH38: >>$$TRIS_BATCHDIR\Logs\%AUTO_JOB_NAME%_stdout.txt | AI38: >>$$TRIS_BATCHDIR\Logs\%AUTO_JOB_NAME%_stderr.txt
A39: TRIS_RH_daily_100_BuildPayrollFiles_vJOB_TR | B39: TRIS_RH_dailyBox | C39: 8 | D39: s(TRIS_RH_daily_080_BuildCommon_FTP_Associations | F39: C:\TRISBatch\BuildDB2LoadFiles\BuildVjob\BuildVjob.exe | L39: /api/core/common/v1/JobSalaryStep/generate-file | M39: Build File for DB2 Load of VSAL_STEP_TBL_TR #RH#DV-HR-TR# CHG0000000xxxxx | N39: CMD | O39: TRIS_RH_dailyBox | P39: TRISBATCH@ameren | Q39: V_TRIS_BATCH | R39: $$TRIS_BATCHDIR\BuildDB2LoadFiles\BuildVsalarystep\BuildVsalarystep.exe | S39: gx,mx | V39: 0 | Z39: 1 | AA39: TRIS | AB39: F | AC39: 3 | AD39: DLTRISTeam@ameren.com | AE39: TRIS_RH_daily_130_BuildPayrollFiles_vSAL_STEP_TBL_TR FAILED. Build File for DB2 Load of VSAL_STEP_TBL_TR. Look in \C\\TRISBatch\\Logs\ on server | AH39: >>$$TRIS_BATCHDIR\Logs\%AUTO_JOB_NAME%_stdout.txt | AI39: >>$$TRIS_BATCHDIR\Logs\%AUTO_JOB_NAME%_stderr.txt
A40: TRIS_RH_daily_110_BuildPayrollFiles_vDEPT_TBL_TR | B40: TRIS_RH_dailyBox | C40: 9 | D40: s(TRIS_RH_daily_100_BuildPayrollFiles_vJOB_TR | F40: C:\TRISBatch\BuildDB2LoadFiles\BuildVdept\BuildVdept.exe | L40: NA | M40: FTP of file to load into VJOB_TR load #RH#DV-HR-TR# CHG0000000xxxxx | N40: FTP | O40: TRIS_RH_dailyBox | P40: ASYSFTPP@SYSC | Q40: V_TRIS_BATCH | S40: gx,mx | V40: 0 | Z40: 1 | AB40: F | AC40: 3 | AD40: DLTRISTeam@ameren.com | AE40: TRIS_RH_daily_140_BuildPayrollFiles_FTP_vJOB_TR FAILED. FTP of file to load into VJOB_TR load. | AJ40: A | AK40: UPLOAD | AL40: $$TRIS_BATCHDIR\\DB2LoadFiles\\VJOB-TR-EXTRACT.txt | AM40: ITP.DATA.JOB | AN40: SYSC.ameren.com | AO40: 0 | AP40: TRISBATCH@ameren | AQ40: Simple
...

Sheet Job Schedule
A1: Please see the bottom Notes for more info on highlighted jobs.
A2: Job Name | B2: Box | C2: Step | D2: Days | E2: Time
A3: TRIS_RH_ARCOS_Daily_Box | D3: su,mo,tu,we,th,fr,sa | E3: 0.5
A4: TRIS_RH_ARCOS_Overtime_Daily | B4: TRIS_RH_ARCOS_Daily_Box | C4: 1
A5: TRIS_RH_ARCOS_HR_Daily | B5: TRIS_RH_ARCOS_Daily_Box | C5: 2 | D5: s(TRIS_RH_ARCOS_Overtime_Daily)
A6: TRIS_RH_ARCOS_Sched_Daily | B6: TRIS_RH_ARCOS_Daily_Box | C6: 3 | D6: s(TRIS_RH_ARCOS_HR_Daily)
A7: TRIS_RH_ARCOS_SFTP_Daily | B7: TRIS_RH_ARCOS_Daily_Box | C7: 4 | D7: s(TRIS_RH_ARCOS_Sched_Daily)
A8: TRIS_RH_ARCOS_Delete_files | B8: TRIS_RH_ARCOS_Daily_Box | C8: 5 | D8: s(TRIS_RH_ARCOS_SFTP_Daily)
A9: TRIS_RH_ARCOS_Weekly_Box | D9: we | E9: 0.25
A10: TRIS_RH_ARCOS_Overtime_Weekly | B10: TRIS_RH_ARCOS_Weekly_Box | C10: 1
A11: TRIS_RH_ARCOS_Yearly_Box | D11: AM_1st_WED_JAN | E11: 0.27083333
A12: TRIS_RH_ARCOS_Overtime_Yearly | B12: TRIS_RH_ARCOS_Yearly_Box | C12: 1
A14: TRIS_RH_Contract_Final | D14: On demand
A15: TRIS_RH_Contract_Final_010_BuildPayrollFiles_vJOB_TR | B15: TRIS_RH_Contract_Final | C15: 1
A16: TRIS_RH_Contract_Final_020_BuildPayrollFiles_vDEPT_TBL_TR | B16: TRIS_RH_Contract_Final | C16: 2 | D16: s(TRIS_RH_Contract_Final_010_BuildPayrollFiles_vJOB_TR)
A17: TRIS_RH_Contract_Final_030_BuildPayrollFiles_vJOBCODE_TR | B17: TRIS_RH_Contract_Final | C17: 3 | D17: s(TRIS_RH_Contract_Final_020_BuildPayrollFiles_vDEPT_TBL_TR)
A18: TRIS_RH_Contract_Final_040_BuildPayrollFiles_vSAL_STEP_TR | B18: TRIS_RH_Contract_Final | C18: 4 | D18: S(TRIS_RH_Contract_Final_030_BuildPayrollFiles_vJOBCODE_TR )
A19: TRIS_RH_Contract_Final_050_BuildPayrollFiles_FTP_vJOB_TR | B19: TRIS_RH_Contract_Final | C19: 5 | D19: S(TRIS_RH_Contract_Final_040_BuildPayrollFiles_vSAL_STEP_TR)
A20: TRIS_RH_Contract_Final_060_BuildPayrollFiles_FTP_vDEPT_TR | B20: TRIS_RH_Contract_Final | C20: 6 | D20: S(TRIS_RH_Contract_Final_050_BuildPayrollFiles_FTP_vJOB_TR)
A21: TRIS_RH_Contract_Final_070_BuildPayrollFiles_FTP_vJOBCODE | B21: TRIS_RH_Contract_Final | C21: 7 | D21: S(TRIS_RH_Contract_Final_060_BuildPayrollFiles_FTP_vDEPT_TR)
A22: TRIS_RH_Contract_Final_080_BuildPayrollFiles_FTP_vSAL | B22: TRIS_RH_Contract_Final | C22: 8 | D22: S(TRIS_RH_Contract_Final_050_BuildPayrollFiles_FTP_vJOB_TR)
A23: TRIS_RH_Contract_Final_200_MF_AR13895 | B23: TRIS_RH_Contract_Final | C23: 9 | D23: S(TRIS_RH_Contract_Final_080_BuildPayrollFiles_FTP_Vsal)
A24: TRIS_RH_Contract_Final_300_Build_HR_History_View | B24: TRIS_RH_Contract_Final | C24: 10 | D24: s(TRIS_RH_Contract_Final_200_MF_AR13895)
A25: TRIS_RH_Contract_Final_410_MF_TR33200 | B25: TRIS_RH_Contract_Final | C25: 11 | D25: s(TRIS_RH_Contract_Final_300_Build_HR_History_View)
A26: TRIS_RH_Contract_Final_420_MF_AR13687 | B26: TRIS_RH_Contract_Final | C26: 12a | D26: s(TRIS_RH_Contract_Final_410_MF_TR33200)
A27: TRIS_RH_Contract_Final_530_Send_Copy_PayrollFile | B27: TRIS_RH_Contract_Final | C27: 13a | D27: s(TRIS_RH_Contract_Final_420_MF_AR13687)
A28: TRIS_RH_Contract_Final_540_Send_Move_PayrollFile | B28: TRIS_RH_Contract_Final | C28: 14a | D28: s(TRIS_RH_Contract_Final_530_Send_Copy_PayrollFile)
A29: TRIS_RH_Contract_Final_550_Send_ToPayroll | B29: TRIS_RH_Contract_Final | C29: 15a | D29: s(TRIS_RH_Contract_Final_540_Send_Move_PayrollFile)
A30: TRIS_RH_Contract_Final_600_MF_TR33206 | B30: TRIS_RH_Contract_Final | C30: 12b | D30: s(TRIS_RH_Contract_Final_410_MF_TR33200)
A32: TRIS_RH_Contract_Preliminary_OnRequest_MF_TR33103N | D32: Failure of mainframe job
A34: TRIS_RH_dailyBox
A35: TRIS_RH_daily_010_BuildCommon_Department | B35: TRIS_RH_dailyBox | C35: 1 | D35: mo,tu,we,th,fr,sa | E35: 0.041666667
A36: TRIS_RH_daily_020_BuildCommon_Employee | B36: TRIS_RH_dailyBox | C36: 2 | D36: s(TRIS_RH_daily_010_BuildCommon_Department)
A37: TRIS_RH_daily_030_BuildCommon_FTP_Department | B37: TRIS_RH_dailyBox | C37: 3 | D37: s(TRIS_RH_daily_020_BuildCommon_Employee
A38: TRIS_RH_daily_040_BuildCommon_FTP_Employee | B38: TRIS_RH_dailyBox | C38: 4 | D38: s(TRIS_RH_daily_030_BuildCommon_FTP_Department
A39: TRIS_RH_daily_050_BuildCommon_FTP_THRDBEmployee | B39: TRIS_RH_dailyBox | C39: 5 | D39: s(TRIS_RH_daily_040_BuildCommon_FTP_Employee
A40: TRIS_RH_daily_070_BuildCommon_Associations | B40: TRIS_RH_dailyBox | C40: 6 | D40: s(TRIS_RH_daily_050_BuildCommon_FTP_THRDBEmployee
A41: TRIS_RH_daily_080_BuildCommon_FTP_Associations | B41: TRIS_RH_dailyBox | C41: 7 | D41: s(TRIS_RH_daily_070_BuildCommon_Associations
A42: TRIS_RH_daily_100_BuildPayrollFiles_vJOB_TR | B42: TRIS_RH_dailyBox | C42: 8 | D42: s(TRIS_RH_daily_080_BuildCommon_FTP_Associations
A43: TRIS_RH_daily_110_BuildPayrollFiles_vDEPT_TBL_TR | B43: TRIS_RH_dailyBox | C43: 9 | D43: s(TRIS_RH_daily_100_BuildPayrollFiles_vJOB_TR
...

Sheet Job to Program Mapping 
B1: Process Name | C1: Job Name | D1: Description | E1: Program
B2: Reconciliation | C2: AR13999 | D2: Copy Job | E2: NA
C3: DB12287N | D3: Load DB2 | E3: NA
C4: DB12005N | D4: Load DB2 | E4: NA | H4: This sheet contains the Mapping of COBOL Programs (Main Programs) Being invoked from the JOB. Typically a Mainframe JOB contains steps, that execute in a sequential order and each step of the JOB executes an Application Programs or Utility Program (Load, Unload, Sort)
C5: AR13895 | D5: Load DB2 | E5: NA
C6: AR13872 | D6: Copy Job | E6: NA
C7: AR13687 | D7: FTP Contract Payroll Files | E7: NA
C8: AR13587 | D8: FTP Executive Payroll Files | E8: NA
B9: Maintain | C9: TR33106N | D9: Maintains table TTR_JOBS | E9: TR014
C10: TR33107 | D10: Maintains table TTR_ASSOCIATIONS | E10: TR015 TR085
C11: TR33102 | D11: HR interface via Common Employee | E11: TR009 TR129
B12: Seniority | C12: TR33136N | D12: Seniority Accrual | E12: TI0510 TR127
B13: TRBE | C13: TR33115N | D13: TRBE Process | E13: TI0504 TI0503 TI0538 TI1003 TI0508
B14: Contract Payroll | C14: TR33103N | D14: Contract Pre Payroll | E14: TR033 TR001 TR039 TR051 TR052 TR003 TR050 TR021 TR117 TR003C TR050C TR021C TR104 TR115 TR105 TR106 TR108 TR004 TR005 TR077 TR029
C15: TR33101N | D15: Contract Daily Payroll | E15: TR001 TR051 TR052 TR003 TR050 TR021 TR003C TR050C TR021C TR105 TR106 TR108 TR004 TR005 TR077 TR029
C16: TR33200 | D16: Contract Final Payroll | E16: TR001 TR039 TR051 TR052 TR003 TR050 TR021 TR003C TR050C TR021C TR105 TR106 TR131 TR108 TR004 TR005 TR060 TR033 TR037
C17: TR33206 | D17: Contract Final (Update sick leave banks/generate reports) | E17: TR109 TR107 TR077 TR042 TR029 TR026 TR135 TR136 TR137 TR111 TR134
B18: Executive Payroll | C18: TR33201 | D18: Executive Final Payroll | E18: TR001 TR033 TR039 TR051 TR052 TR003 TR050 TR021 TR103 TR004 TR005 TR044 TR060 TR077 TR029 TR026 TR135 TR128 TR037
B19: Overtime | C19: TR33108 | D19: Delayed Overtime Bank Charges | E19: TR008
C20: TR33211 | D20: Weekly Overtime Report (Missouri) | E20: TR053
B21: Monthly | C21: TR33311 | D21: Seniority List Local | E21: TR090 TR091 TR092 TR093 TR094 TR083
C22: TR33137 | D22: Absence Exception Report | E22: TI0545 TR078 (A,B,C,D,E) TR086
C23: TR33408 | D23: Sick Leave Summary Report | E23: TI0544 TR058
B24: Quaterly | C24: TR33400 | D24: E&C Report (Project / Non-Project) | E24: TR121 TR122
C25: TR33402 | D25: Seniority List Union Local | E25: TR095 TR096 TR097
C26: TR33407 | D26: Overtime Report | E26: TR087
C27: TR33401 | D27: Sick Leave Reports | E27: TR130 TI0544 TR041 TR099 TR049
B28: Yearly | C28: TR33445 | D28: Vacation Carry Over and update report | E28: TR114
C29: TR33446 | D29: Annual Sick Leave and Vacation Summary | E29: TR110 TR139 TR140 TR098 TI0543 TR070 TR071 TR072 TR074 TR132
C30: TR33406 | D30: CIPS Local 702 Sick Leave Report | E30: TR043
B31: On Request | C31: TR33442 | D31: Build Holidays (Runs October) | E31: TI0505 TI1004
C32: TR33451 | D32: Vacation Allotment Management Employee Report (Runs October) | E32: TR113
C33: TR33440 | D33: Vacation Allotment Contract Employee Report (Runs October) | E33: TR113
C34: TR33000 | D34: RECALCULATE SICK LEAVE BALANCE | E34: TR426
C35: TR33112 | D35: Executive Preliminary Payroll | E35: TR033 TR001 TR039 TR051 TR052 TR003 TR050 TR021 TR103 TR004 TR005 TR029 TR048 TR128
B36: Stored PROCs | C36: TR33122 | D36: OVERTIME EQUALIZATION REPORT | E36: TR126 (2)
C37: TR33142 | D37: Seniority | E37: TR081 (4)
C38: TR33145 | D38: Vacation Summary | E38: TR133 (3)
C39: TR33128 | D39: Overtime Adjustment Report | E39: TR125 (1)
C40: TR33120 | D40: Overtime Canvass (TTR_JCL -- INSERTS GOOD) | E40: TR027

Sheet Program Mapping
B1: Job | C1: Program | D1: Legacy Autosys Job
A2: Maintain | B2: TR33106N | D2: TRIS_RH_daily_410_MF_TR33106
B3: TR33107 | C3: TR015 TR085 | D3: TRIS_RH_daily_420_MF_TR33107
B4: TR33102 | C4: TR009 TR129 | D4: TRIS_RH_daily_430_MF_TR33102
A5: Seniority | B5: TR33136N | C5: TI0510 TR127 | D5: TRIS_RH_daily_440_MF_TR33136
A6: TRBE | B6: TR33115N | C6: TI0504 TI0503 TI0538 TI1003 TI0508 | D6: TRIS_RH_daily_450_MF_TR33115
A7: Contract Payroll | B7: TR33101N | C7: TR001 TR051 TR052 TR003 TR050 TR021 TR003C TR050C TR021C TR105 TR106 TR108 TR004 TR005 TR077 TR029 | D7: TRIS_RH_daily_700_MF_TR33101N
B8: TR33103N | C8: TR033 TR001 TR039 TR051 TR052 TR003 TR050 TR021 TR117 TR003C TR050C TR021C TR104 TR115 TR105 TR106 TR108 TR004 TR005 TR077 TR029 | D8: TRIS_RH_Contract_Preliminary_OnRequest_MF_TR33103N
B9: TR33200 | C9: TR001 TR039 TR051 TR052 TR003 TR050 TR021 TR003C TR050C TR021C TR105 TR106 TR131 TR108 TR004 TR005 TR060 TR033 TR037 | D9: TRIS_RH_Contract_Final_410_MF_TR33200
B10: TR33206 | C10: TR109 TR107 TR077 TR042 TR029 TR026 TR135 TR136 TR137 TR111 TR134 | D10: TRIS_RH_Contract_Final_600_MF_TR33206
A11: Executive Payroll | B11: TR33201 | C11: TR001 TR033 TR039 TR051 TR052 TR003 TR050 TR021 TR103 TR004 TR005 TR044 TR060 TR077 TR029 TR026 TR135 TR128 TR037 | D11: TRIS_RH_Executive_Final_410_MF_TR33201
A12: Overtime | B12: TR33108 | C12: TR008 | D12: TRIS_RH_Daily_everyday_0005_DelayedOTBanks_MF_TR33108
B13: TR33211 | C13: TR053
A14: Monthly | B14: TR33311 | C14: TR090 TR091 TR092 TR093 TR094 TR083
B15: TR33137 | C15: TI0545 TR078 (A,B,C,D,E) TR086
B16: TR33408 | C16: TI0544 TR058
A17: Quaterly | B17: TR33400 | C17: TR121 TR122
B18: TR33402 | C18: TR095 TR096 TR097
B19: TR33407 | C19: TR087
B20: TR33401 | C20: TR130 TI0544 TR041 TR099 TR049
A21: Yearly | B21: TR33445 | C21: TR114 | D21: TRIS_RH_yearly_Jan25_1730_MF_TR33445
B22: TR33446 | C22: TR110 TR139 TR140 TR098 TI0543 TR070 TR071 TR072 TR074 TR132 | D22: TRIS_RH_yearly_Jan25_1800_MF_TR33446
B23: TR33406 | C23: TR043 | D23: TRIS_RH_yearly_Jan25_2000_MF_TR33406
A24: On Request | B24: TR33442 | C24: TI0505 TI1004
B25: TR33451 | C25: TR113
B26: TR33440 | C26: TR113
B27: TR33000 | C27: TR426 | D27: TRIS_RN_Sick_Leave_Recalculate_Bank_Balances_MF_TR33000
B28: TR33112 | C28: TR033 TR001 TR039 TR051 TR052 TR003 TR050 TR021 TR103 TR004 TR005 TR029 TR048 TR128 | D28: TRIS_RH_Executive_Preliminary_OnRequest_MF_TR33112
A29: MuleSoft Integration | D29: TRIS_RH_monthly_020_PayrollAccruals
D30: TRIS_RH_monthly_030_PayrollDistributionInterface
A34: ARCO Integration | D34: TRIS_RH_ARCOS_HR_Daily
D35: TRIS_RH_ARCOS_Overtime_Daily
D36: TRIS_RH_ARCOS_Overtime_Weekly
D37: TRIS_RH_ARCOS_Overtime_Yearly
D38: TRIS_RH_ARCOS_Sched_Daily
A44: Workday Integration | D44: TRIS_RH_Contract_Final_550_Send_ToPayroll
D45: TRIS_RH_daily_445_workday_Seniority_Interface
D46: TRIS_RH_Daily_everyday_1900_workday_FMLA_Interface
D47: TRIS_RH_Executive_Final_550_Send_ToPayroll
A51: Maximo Integration | D51: TRIS_RH_monthly_100_MaximoAccountingInterface

Sheet TRIS Autosys Jobs
A1: Please see the bottom Notes for more info on highlighted jobs.
A2: Job Name | B2: New TRIS & C# | C2: Description | D2: SME -- Comments | E2: Condition | F2: Job Type | G2: Box Name | H2: Owner | I2: Machine | J2: Command | K2: Permissions | L2: JCL library | M2: JCL member | N2: Has Date Condition | O2: Days of Week | P2: Start Time | Q2: Run Calendar | R2: Exclude Calendar | S2: Alarm | T2: Profile | U2: Send Notification | V2: Schedule Priority | W2: Email Notified | X2: Email Message | Y2: Mainframe Condtion Code | Z2: Start Mins | AA2: std out file | AB2: std err file | AC2: FTP transfer type | AD2: FTP transfer direction | AE2: FTP local name | AF2: FTP remote name | AG2: FTP server name | AH2: FTP use ssl | AI2: FTP local user | AJ2: FTP user type | AK2: max run alarm | AL2: box terminator | AM2: term run time | AN2: Status
A3: TRIS_RH_ARCOS_Daily_Box | C3: TRIS ARCOS Daily Interface Files CHG0000000xxxxx | F3: BOX | H3: TRISBATCH@ameren | K3: gx,mx | N3: 1 | O3: su,mo,tu,we,th,fr,sa | P3: 0.54166667 | S3: 1 | V3: 3
A4: TRIS_RH_ARCOS_HR_Daily | B4: /api/core/payroll/v1/ARCOSHRInterface/strike/process | C4: TRIS daily ARCOS HR interface #RH#DV-HR-TR# CHG CHG0000000xxxxx | E4: s(TRIS_RH_ARCOS_Overtime_Daily) | F4: CMD | G4: TRIS_RH_ARCOS_Daily_Box | H4: TRISBATCH@ameren | I4: V_TRIS_BATCH | J4: $$TRIS_BATCHDIR\ARCOSHRInterface\ARCOSHRInterface.exe | K4: gx,mx | N4: 0 | S4: 1 | T4: TRIS | U4: F | V4: 3 | W4: DLTRISTeam@ameren.com | X4: TRIS_RH_ARCOS_HR_Daily FAILED. | AA4: >>$$TRIS_BATCHDIR\Logs\%AUTO_JOB_NAME%_stdout.txt | AB4: >>$$TRIS_BATCHDIR\Logs\%AUTO_JOB_NAME%_stderr.txt
A5: TRIS_RH_ARCOS_Overtime_Daily | B5: /api/core/payroll/v1/ArcosOvertimeInterface/interface | C5: TRIS daily ARCOS Overtime interface #RH#DV-HR-TR# CHG0000000xxxxx | F5: CMD | G5: TRIS_RH_ARCOS_Daily_Box | H5: TRISBATCH@ameren | I5: V_TRIS_BATCH | J5: $$TRIS_BATCHDIR\ARCOSOvertimeInterface\ARCOSOvertimeInterface.exe | K5: gx,mx | N5: 0 | S5: 1 | T5: TRIS | U5: F | V5: 3 | W5: DLTRISTeam@ameren.com | X5: TRIS_RH_ARCOS_Overtime_Daily FAILED. | AA5: >>$$TRIS_BATCHDIR\Logs\%AUTO_JOB_NAME%_stdout.txt | AB5: >>$$TRIS_BATCHDIR\Logs\%AUTO_JOB_NAME%_stderr.txt
A6: TRIS_RH_ARCOS_Overtime_Weekly | B6: /api/core/payroll/v1/ARCOSOvertimeWeekly/build-all-standings | C6: TRIS weekly ARCOS Build Next Standing #RN#DV-HR-TR# CHG0000000xxxxx | F6: CMD | G6: TRIS_RH_ARCOS_Weekly_Box | H6: TRISBATCH@ameren | I6: V_TRIS_BATCH | J6: $$TRIS_BATCHDIR\ARCOSOvertimeWeeklyProcess\ARCOSOvertimeWeeklyProcess.exe | K6: gx,mx | N6: 0 | S6: 1 | T6: TRIS | U6: F | V6: 3 | W6: DLTRISTeam@ameren.com | X6: TRIS_RH_ARCOS_Overtime_Weekly FAILED. | AA6: >>$$TRIS_BATCHDIR\Logs\%AUTO_JOB_NAME%_stdout.txt | AB6: >>$$TRIS_BATCHDIR\Logs\%AUTO_JOB_NAME%_stderr.txt
A7: TRIS_RH_ARCOS_Overtime_Yearly | B7: /api/core/payroll/v1/ARCOSOvertimeYearly/rezero-standings | C7: TRIS ARCOS Yearly -- Re-Zero Standings -- Jim Barnett 314-630-7969 #RN#DV-HR-TR# CHG0000000xxxxx | F7: CMD | G7: TRIS_RH_ARCOS_Yearly_Box | H7: TRISBATCH@ameren | I7: V_TRIS_BATCH | J7: $$TRIS_BATCHDIR\ARCOSOvertimeYearlyProcess\ARCOSOvertimeYearlyProcess.exe | K7: gx,mx | N7: 0 | S7: 1 | T7: TRIS | U7: F | V7: 3 | W7: DLTRISTeam@ameren.com | X7: TRIS_RH_ARCOS_Overtime_Yearly FAILED. | AA7: >>$$TRIS_BATCHDIR\Logs\%AUTO_JOB_NAME%_stdout.txt | AB7: >>$$TRIS_BATCHDIR\Logs\%AUTO_JOB_NAME%_stderr.txt
A8: TRIS_RH_ARCOS_Sched_Daily | B8: /api/core/payroll/v1/ARCOSSchedulingInterface/build-schedule-file | C8: TRIS daily ARCOS Schedule interface #RH#DV-HR-TR# CHG CHG0000000xxxxx | E8: s(TRIS_RH_ARCOS_HR_Daily) | F8: CMD | G8: TRIS_RH_ARCOS_Daily_Box | H8: TRISBATCH@ameren | I8: V_TRIS_BATCH | J8: $$TRIS_BATCHDIR\ARCOSScheduleInterface\ARCOSSchedulingInterface.exe | K8: gx,mx | N8: 0 | S8: 1 | T8: TRIS | U8: F | V8: 3 | W8: DLTRISTeam@ameren.com | X8: TRIS_RH_ARCOS_Sched_Daily FAILED. | AA8: >>$$TRIS_BATCHDIR\Logs\%AUTO_JOB_NAME%_stdout.txt | AB8: >>$$TRIS_BATCHDIR\Logs\%AUTO_JOB_NAME%_stderr.txt
A9: TRIS_RH_ARCOS_Weekly_Box | B9: /api/core/payroll/v1/ARCOSOvertimeWeekly/build-all-standings | C9: TRIS ARCOS Weekly Create next Standing CHG0000000xxxxx | F9: BOX | H9: TRISBATCH@ameren | K9: gx,mx | N9: 1 | O9: we | P9: 0.25 | S9: 1 | V9: 3
A10: TRIS_RH_ARCOS_Yearly_Box | B10: /api/core/payroll/v1/ARCOSOvertimeYearly/rezero-standings | C10: TRIS ARCOS Yearly -- Re-Zero Standings -- Jim Barnett 314-630-7969 CHG0000000xxxxx | F10: BOX | H10: TRISBATCH@ameren | K10: gx,mx | N10: 1 | O10: we | P10: 0.27083333 | S10: 1 | V10: 3
A11: TRIS_RH_Contract_Final | C11: This runs the TRIS portion of the contract payroll | F11: BOX | H11: TRISBATCH@ameren | K11: gx,mx | N11: 0 | S11: 1 | V11: 3
A12: TRIS_RH_Contract_Final_010_BuildPayrollFiles_vJOB_TR | B12: /api/core/notification/v1/jobs/buildFile | C12: Build File for DB2 Load of VJOB_TR #RH#DV-HR-TR# CHG0000000xxxxx | F12: CMD | G12: TRIS_RH_Contract_Final | H12: TRISBATCH@ameren | I12: V_TRIS_BATCH | J12: $$TRIS_BATCHDIR\BuildDB2LoadFiles\BuildVjob\BuildVjob.exe | K12: gx,mx | N12: 0 | S12: 1 | T12: TRIS | U12: F | V12: 3 | W12: DLTRISTeam@ameren.com | X12: TRIS_RH_Contract_Final_010_BuildPayrollFiles_vJOB_TR FAILED | AA12: >>$$TRIS_BATCHDIR\Logs\%AUTO_JOB_NAME%_stdout.txt | AB12: >>$$TRIS_BATCHDIR\Logs\%AUTO_JOB_NAME%_stderr.txt
A13: TRIS_RH_Contract_Final_020_BuildPayrollFiles_vDEPT_TBL_TR | B13: /api/core/notification/v1/departments/buildFile | C13: Build File for DB2 Load of VDEPT_TBL_TR #RH#DV-HR-TR# CHG0000000xxxxx | E13: s(TRIS_RH_Contract_Final_010_BuildPayrollFiles_vJOB_TR) | F13: CMD | G13: TRIS_RH_Contract_Final | H13: TRISBATCH@ameren | I13: V_TRIS_BATCH | J13: $$TRIS_BATCHDIR\BuildDB2LoadFiles\BuildVdept\BuildVdept.exe | K13: gx,mx | N13: 0 | S13: 1 | T13: TRIS | U13: F | V13: 3 | W13: DLTRISTeam@ameren.com | X13: TRIS_RH_Contract_Final_020_BuildPayrollFiles_vDEPT_TBL_TR FAILED | AA13: >>$$TRIS_BATCHDIR\Logs\%AUTO_JOB_NAME%_stdout.txt | AB13: >>$$TRIS_BATCHDIR\Logs\%AUTO_JOB_NAME%_stderr.txt
A14: TRIS_RH_Contract_Final_030_BuildPayrollFiles_vJOBCODE_TR | B14: /api/core/notification/v1/jobcodes/buildFile | C14: Build File for DB2 Load of VJOBCODE_TBL_TR #RH#DV-HR-TR# CHG0000000xxxxx | E14: s(TRIS_RH_Contract_Final_020_BuildPayrollFiles_vDEPT_TBL_TR) | F14: CMD | G14: TRIS_RH_Contract_Final | H14: TRISBATCH@ameren | I14: V_TRIS_BATCH | J14: $$TRIS_BATCHDIR\BuildDB2LoadFiles\BuildVjobcode\BuildVjobcode.exe | K14: gx,mx | N14: 0 | S14: 1 | T14: TRIS | U14: F | V14: 3 | W14: DLTRISTeam@ameren.com | X14: TRIS_RH_Contract_Final_030_BuildPayrollFiles_vJOBCODE_TBL_TR FAILED | AA14: >>$$TRIS_BATCHDIR\Logs\%AUTO_JOB_NAME%_stdout.txt | AB14: >>$$TRIS_BATCHDIR\Logs\%AUTO_JOB_NAME%_stderr.txt
A15: TRIS_RH_Contract_Final_040_BuildPayrollFiles_vSAL_STEP_TR | B15: /api/core/common/v1/JobSalaryStep/generate-file | C15: Build File for DB2 Load of VSAL_STEP_TBL_TR #RH#DV-HR-TR# CHG0000000xxxxx | E15: s(TRIS_RH_Contract_Final_030_BuildPayrollFiles_vJOBCODE_TR) | F15: CMD | G15: TRIS_RH_Contract_Final | H15: TRISBATCH@ameren | I15: V_TRIS_BATCH | J15: $$TRIS_BATCHDIR\BuildDB2LoadFiles\BuildVsalarystep\BuildVsalarystep.exe | K15: gx,mx | N15: 0 | S15: 1 | T15: TRIS | U15: F | V15: 3 | W15: DLTRISTeam@ameren.com | X15: TRIS_RH_Contract_Final_040_BuildPayrollFiles_vSAL_STEP_TR FAILED | AA15: >>$$TRIS_BATCHDIR\Logs\%AUTO_JOB_NAME%_stdout.txt | AB15: >>$$TRIS_BATCHDIR\Logs\%AUTO_JOB_NAME%_stderr.txt
A16: TRIS_RH_Contract_Final_050_BuildPayrollFiles_FTP_vJOB_TR | B16: FTP Jobs Not Applicable | C16: FTP of file to load into VJOB_TR load #RH#DV-HR-TR# CHG0000000xxxxx | E16: s(TRIS_RH_Contract_Final_040_BuildPayrollFiles_vSAL_STEP_TR) | F16: FTP | G16: TRIS_RH_Contract_Final | H16: ASYSFTPP@SYSC | I16: V_TRIS_BATCH | K16: gx,mx | N16: 0 | S16: 1 | U16: F | V16: 3 | W16: DLTRISTeam@ameren.com | X16: TRIS_RH_Contract_Final_050_BuildPayrollFiles_FTP_vJOB_TR FAILED | AC16: A | AD16: UPLOAD | AE16: $$TRIS_BATCHDIR\\DB2LoadFiles\\VJOB-TR-EXTRACT.txt | AF16: ITP.DATA.JOB | AG16: SYSC.ameren.com | AH16: 0 | AI16: TRISBATCH@ameren | AJ16: Simple
A17: TRIS_RH_Contract_Final_060_BuildPayrollFiles_FTP_vDEPT_TR | B17: FTP Jobs Not Applicable | C17: FTP of file to load into VDEPT_TBL_TR load #RH#DV-HR-TR# CHG0000000xxxxx | E17: s(TRIS_RH_Contract_Final_050_BuildPayrollFiles_FTP_vJOB_TR) | F17: FTP | G17: TRIS_RH_Contract_Final | H17: ASYSFTPP@SYSC | I17: V_TRIS_BATCH | K17: gx,mx | N17: 0 | S17: 1 | U17: F | V17: 3 | W17: DLTRISTeam@ameren.com | X17: TRIS_RH_Contract_Final_060_BuildPayrollFiles_FTP_vDEPT_TR FAILED | AC17: A | AD17: UPLOAD | AE17: $$TRIS_BATCHDIR\\DB2LoadFiles\\VDEPT-TBL-TR-EXTRACT.txt | AF17: ITP.DATA.DEPT | AG17: SYSC.ameren.com | AH17: 0 | AI17: TRISBATCH@ameren | AJ17: Simple
A18: TRIS_RH_Contract_Final_070_BuildPayrollFiles_FTP_vJOBCODE | B18: FTP Jobs Not Applicable | C18: FTP of file to load into VJOBCODE_TBL_TR load #RH#DV-HR-TR# CHG0000000xxxxx | E18: s(TRIS_RH_Contract_Final_060_BuildPayrollFiles_FTP_vDEPT_TR) | F18: FTP | G18: TRIS_RH_Contract_Final | H18: ASYSFTPP@SYSC | I18: V_TRIS_BATCH | K18: gx,mx | N18: 0 | S18: 1 | U18: F | V18: 3 | W18: DLTRISTeam@ameren.com | X18: TRIS_RH_Contract_Final_070_BuildPayrollFiles_FTP_vJOBCODE FAILED | AC18: A | AD18: UPLOAD | AE18: $$TRIS_BATCHDIR\\DB2LoadFiles\\VJOBCODE-TBL-TR-EXTRACT.txt | AF18: ITP.DATA.JOBCODE | AG18: SYSC.ameren.com | AH18: 0 | AI18: TRISBATCH@ameren | AJ18: Simple
A19: TRIS_RH_Contract_Final_080_BuildPayrollFiles_FTP_vSAL | B19: FTP Jobs Not Applicable | C19: FTP of file to load into VSAL_STEP_TBL_TR load #RH#DV-HR-TR# CHG0000000xxxxx | E19: s(TRIS_RH_Contract_Final_070_BuildPayrollFiles_FTP_vJOBCODE) | F19: FTP | G19: TRIS_RH_Contract_Final | H19: ASYSFTPP@SYSC | I19: V_TRIS_BATCH | K19: gx,mx | N19: 0 | S19: 1 | U19: F | V19: 3 | W19: DLTRISTeam@ameren.com | X19: TRIS_RH_Contract_Final_080_BuildPayrollFiles_FTP_vSAL FAILED | AC19: A | AD19: UPLOAD | AE19: $$TRIS_BATCHDIR\\DB2LoadFiles\\VSAL-STEP-TBL-TR-EXTRACT.txt | AF19: ITP.DATA.SAL.STP | AG19: SYSC.ameren.com | AH19: 0 | AI19: TRISBATCH@ameren | AJ19: Simple
A20: TRIS_RH_Contract_Final_200_MF_AR13895 | B20: Cobol DB2 load Not in Autosys | C20: Loads the FTP files that contained HR data for Payroll into DB2 Tables #RH#DV-HR-TR# CHG0000000xxxxx | D20: OBULA | E20: s(TRIS_RH_Contract_Final_080_BuildPayrollFiles_FTP_vSAL) | F20: ZOS | G20: TRIS_RH_Contract_Final | H20: ESPAE | I20: V_TRIS_TRJobs2MF | L20: CF.STARTPDS | M20: AR13895 | N20: 0 | S20: 1 | U20: F | W20: DLTRISTeam@ameren.com | X20: TRIS_RH_Contract_Final_200_MF_AR13895 FAILED. Loads the FTP files that contained HR data for Payroll into DB2 Tables | Y20: action=STOP,rc=4\:4095,result=FAILURE
A21: TRIS_RH_Contract_Final_300_Build_HR_History_View | C21: Fills tables for view VJOB_TR_EFF which allows the HR History records to have a start and end date versus just an effective date. #RH#DV-HR-TR# CHG00000000xxxx | E21: s(TRIS_RH_Contract_Final_200_MF_AR13895) | F21: CMD | G21: TRIS_RH_Contract_Final | H21: TRISBATCH@ameren | I21: V_TRIS_BATCH | J21: $$TRIS_BATCHDIR\PSJobViewRefresh\PS2TRIS.exe | K21: gx,mx | N21: 0 | S21: 1 | T21: TRIS | U21: F | V21: 3 | W21: DLTRISTeam@ameren.com | X21: TRIS_RH_Contract_Final_300_Build_HR_History_View FAILED. Fills tables for view VJOB_TR_EFF which allows the HR History records to have a start and end date versus just an effective date. Look in \C\\TRISBatch\\Logs\ on server | AA21: >>$$TRIS_BATCHDIR\Logs\%AUTO_JOB_NAME%_stdout.txt | AB21: >>$$TRIS_BATCHDIR\Logs\%AUTO_JOB_NAME%_stderr.txt
A22: TRIS_RH_Contract_Final_410_MF_TR33200 | B22: TR_RN_ContractPayroll_TR33200_Trigger_HTTP | C22: Mainframe Contract Payroll processing that produces Payroll file that is used in TRIS_RH_Contract_Final_550_Send_ToPayroll to build a JSON request to send to Workday #RH#DV-HR-TR# CHG0000000xxxxx | D22: OBULA | E22: s(TRIS_RH_Contract_Final_300_Build_HR_History_View) | F22: ZOS | G22: TRIS_RH_Contract_Final | H22: ESPAE | I22: V_TRIS_TRJobs2MF | L22: UE.STARTPDS | M22: TR33200 | N22: 0 | S22: 1 | U22: F | W22: DLTRISTeam@ameren.com | X22: TRIS_RH_Contract_Final_410_MF_TR33200 FAILED. Mainframe Contract Payroll processing that produces Payroll file that is used in TRIS_RH_Contract_Final_550_Send_ToPayroll to build a JSON request to send to Workday | Y22: action=STOP,rc=1\:4095,result=FAILURE
A23: TRIS_RH_Contract_Final_420_MF_AR13687 | B23: Cobol DB2 load Not in Autosys | C23: FTPs Mainframe Payroll File built in TRIS_RH_Contract_Final_410_MF_TR33200 to Autosys server #RH#DV-HR-TR# CHG0000000xxxxx | D23: OBULA | E23: s(TRIS_RH_Contract_Final_410_MF_TR33200) | F23: ZOS | G23: TRIS_RH_Contract_Final | H23: ESPAE | I23: V_TRIS_TRJobs2MF | L23: CF.STARTPDS | M23: AR13687 | N23: 0 | S23: 1 | U23: F | W23: DLTRISTeam@ameren.com | X23: TRIS_RH_Contract_Final_420_MF_AR13687 FAILED. FTPs Mainframe Payroll File built in TRIS_RH_Contract_Final_410_MF_TR33200 to Autosys server | Y23: action=STOP,rc=1\:4095,result=FAILURE
